
try
{
    let numerator=10;
    let denominator=a;
    console.log(numerator/denominator);
    console.log(a);
}

catch(error)
{
    console.log("Error occured in this program");
    console.log("Error is "+error);
}
finally
{
    console.log("The finally block will execute in any situation");
}


